Workbook

Sheet 0. Instruções
A1: LEITE DE ROSAS | BRIEFING DE DESENVOLVIMENTO DE PRODUTO — HPPC
A2: Higiene Pessoal, Perfumaria e Cosméticos · Processo Stage-Gate · Documento vivo, versionado por projeto
A4: COMO USAR ESTE ARQUIVO
A5: # | B5: Passo | C5: Detalhe
A6: 1 | B6: Duplique o arquivo por projeto | C6: Um arquivo por ideia de produto. Nomeie como BRF_<ano>_<nº>_<nome de trabalho>.xlsx e registre o mesmo código na aba 1.
A7: 2 | B7: Preencha apenas as células amarelas | C7: Todo o resto é fórmula. Se você digitar por cima de uma fórmula, o modelo para de recalcular e o número deixa de ser confiável.
A8: 3 | B8: Vá na ordem das abas | C8: 1 Briefing → 2 Mercado → 3 Formulação → 4 Embalagem → 5 Custos → 6 Viabilidade. As abas 7 a 10 consolidam a decisão.
A9: 4 | B9: Rode o Scorecard (aba 7) antes de pedir aprovação | C9: O score ponderado é o critério de priorização de portfólio. Projeto abaixo do corte não entra em fila de desenvolvimento.
A10: 5 | B10: Leve ao gate com as abas 6, 7 e 9 impressas | C10: Viabilidade, priorização e riscos são o mínimo que a Diretoria precisa para decidir GO / NO-GO / AJUSTAR.
A12: LEGENDA DE CORES
B13: Formato | C13: Significado
B14: Exemplo | C14: Célula de ENTRADA — fundo amarelo, fonte azul. É aqui que você digita.
B15: Exemplo | C15: Célula CALCULADA na própria aba — fonte preta em negrito. Não digite por cima.
B16: Exemplo | C16: Célula que PUXA outra aba — fonte verde. Para mudar o valor, mude na aba de origem.
A18: CONTEXTO ESTRATÉGICO — POR QUE ESTE BRIEFING EXISTE
A19: # | B19: Vetor | C19: Leitura
A20: 1 | B20: Concentração de portfólio | C20: A maior parte do faturamento está concentrada em pouquíssimos SKUs. Qualquer choque de demanda, de canal ou de matéria-prima nesses itens atinge o caixa inteiro. Desenvolver produto novo aqui não é inovação de vitrine: é redução de risco.
A21: 2 | B21: Margem e caixa restritos | C21: Com margem apertada e caixa curto, todo projeto precisa justificar payback curto, capex mínimo e, sempre que possível, produção em ativo já existente ou terceirizada. A aba 6 força essa conversa com número.
A22: 3 | B22: Ativo de marca subaproveitado | C22: Leite de Rosas é marca quase centenária, com reconhecimento espontâneo altíssimo e território próprio (cuidado, frescor, tradição, o rosa). Extensão de linha bem-feita compra distribuição mais barato do que marca nova.
A23: 4 | B23: Risco de canibalização | C23: Como a base é concentrada, produto novo mal posicionado rouba volume do carro-chefe em vez de somar. O Scorecard (aba 7) pontua isso explicitamente.
A24: 5 | B24: Disciplina de gate | C24: O objetivo do arquivo é matar ideia ruim cedo e barato. Um NO-GO no Gate 1 é resultado positivo do processo, não fracasso.
A26: O QUE COMPÕE O CUSTO — E O QUE COSTUMA FICAR DE FORA
A27: # | B27: Item | C27: Onde entra
A28: 1 | B28: Impostos recuperáveis na compra | C28: O custo de uma matéria-prima é o preço da nota MENOS os créditos que a empresa aproveita. Usar o preço cheio infla o custo e mata projeto bom. → Aba 5 · colunas de imposto recuperável
A29: 2 | B29: Frete de entrada e seguro sobre a compra | C29: Insumo importado ou de outro estado chega mais caro do que o preço de tabela do fornecedor. → Aba 5 · colunas de frete inbound
A30: 3 | B30: Sobre-enchimento | C30: Encher 202 g para declarar 200 g é 1% de matéria-prima doada em todo lote. → Aba 5 · bloco 5.1
A31: 4 | B31: Perdas e refugo por etapa | C31: Pesagem, fabricação, envase, encaixotamento e refugo de embalagem. Cada etapa come um pedaço. → Aba 5 · blocos 5.1, 5.2 e 5.3
A32: 5 | B32: Setup, limpeza e troca de lote | C32: Higienização entre lotes é obrigatória em cosmético e em lote pequeno chega a custar mais que a produção. → Aba 5 · bloco 5.1
A33: 6 | B33: Tamanho do lote | C33: MOD e GGF são rateados por hora ocupada. Sem definir o lote, o custo unitário é chute. → Aba 5 · bloco 5.1
A34: 7 | B34: Análises de qualidade por lote e amostras de retenção | C34: Custo por lote e produto que sai do estoque sem virar venda. → Aba 5 · bloco 5.7
A35: 8 | B35: Amortização de ferramental e moldes | C35: Investimento diluído nas unidades que o molde vai produzir. → Aba 5 · bloco 5.7
A36: 9 | B36: Obsolescência e validade | C36: Embalagem encalhada por troca de arte e granel vencido. → Aba 5 · bloco 5.7
A37: 10 | B37: Custo financeiro do estoque | C37: Dinheiro parado em matéria-prima e produto acabado tem custo, ainda mais com caixa curto. → Aba 5 · bloco 5.7
A38: 11 | B38: Royalties e licenciamento | C38: Marca licenciada, personagem, fragrância exclusiva. → Aba 5 · bloco 5.7
A39: 12 | B39: Terceirização por toll | C39: A taxa do terceirista já embute MOD e GGF. Somar os dois é contar duas vezes. → Aba 5 · bloco 5.7
... A45: 18 | B45: Diferença de alíquota por estado | C45: O mesmo produto tem margem diferente por UF. Rode a aba 5 uma vez por estado relevante. → Aba 5 · bloco 5.9
A47: PREMISSAS E FONTES
A48: # | B48: Item | C48: Origem / observação
A49: 1 | B49: Números de negócio (receita, margem, dívida, concentração de SKU) | C49: Contexto informado pelo usuário. Nenhum valor financeiro real foi preenchido no arquivo — todas as células de dinheiro estão em branco ou com exemplo ilustrativo marcado como tal.
A50: 2 | B50: Linha de exemplo das tabelas | C50: Valores ILUSTRATIVOS, apenas para mostrar formato esperado. Apague antes de usar em projeto real.
...

Sheet 1. Briefing
A1: 1 · BRIEFING DO PRODUTO
A2: Preencha as células amarelas. A coluna da direita explica o que se espera da resposta.
A4: 1.1 IDENTIFICAÇÃO DO PROJETO
A5: Campo | B5: Resposta | C5: Orientação de preenchimento
A6: Código do projeto | C6: Padrão BRF_<ano>_<nº sequencial>. Ex.: BRF_2026_004.
A7: Nome de trabalho | C7: Nome interno, não é o nome comercial. Ex.: 'Desodorante Creme Sensitive'.
A8: Marca / arquitetura | C8: Leite de Rosas (extensão), Leite de Rosas sub-marca, marca do portfólio ou marca nova.
A9: Categoria HPPC | C9: Desodorante, higiene corporal, cuidado facial, cabelos, infantil, perfumaria, higiene íntima etc.
A10: Tipo de projeto | C10: Novo produto | Extensão de linha | Renovação de fórmula | Novo tamanho | Restyling de embalagem | Redução de custo.
A11: Solicitante / área | C11: Quem abriu a demanda e a área responsável pela defesa do projeto no gate.
A12: Patrocinador (Diretoria) | C12: Diretor que responde pelo projeto perante a Diretoria Executiva.
A13: Data de abertura | C13: Data em que o briefing foi aberto.
A14: Gate atual | C14: G0 Ideia | G1 Conceito | G2 Viabilidade | G3 Desenvolvimento | G4 Industrialização | G5 Lançamento.
A15: Prioridade declarada | C15: Alta | Média | Baixa. Prioridade declarada é hipótese; o Scorecard (aba 7) é o que vale.
A17: 1.2 CONTEXTO E RACIONAL — POR QUE ESTE PRODUTO, POR QUE AGORA
A18: Campo | B18: Resposta | C18: Orientação de preenchimento
A19: Problema ou oportunidade | C19: Uma frase objetiva. O que existe hoje no mercado ou no consumidor que justifica gastar dinheiro nisso.
A20: Por que agora | C20: Gatilho de timing: mudança de hábito, movimento de concorrente, janela de canal, sazonalidade, mudança regulatória.
A21: Encaixe estratégico | C21: Como reduz a concentração de faturamento em poucos SKUs, ou como defende o carro-chefe.
A22: O que acontece se não fizermos | C22: O custo de não fazer. Se a resposta for 'nada', o projeto provavelmente não deveria existir.
A23: Alavanca da marca usada | C23: Que ativo da Leite de Rosas o produto empresta: reconhecimento, território de frescor/cuidado, o rosa, tradição, distribuição.
A25: 1.3 OBJETIVO E METAS
A26: Campo | B26: Resposta | C26: Orientação de preenchimento
A27: Objetivo do produto (1 frase) | C27: Comece com um verbo. Ex.: 'Capturar o consumidor de pele sensível que hoje troca a marca por dermocosmético'.
A28: Meta de volume — Ano 1 (un.) | C28: Unidades vendidas no primeiro ano cheio. Este número alimenta a aba 6.
A29: Meta de receita líquida — Ano 1 | C29: Deve bater com o resultado calculado na aba 6. Se não bater, uma das duas premissas está errada.
A30: Margem de contribuição-alvo (%) | C30: Piso de margem aceitável para o projeto seguir. Digite como percentual (ex.: 35%).
A31: Distribuição-alvo (nº de PDVs) | C31: Pontos de venda ativos ao fim do Ano 1.
A33: 1.4 CONSUMIDOR E OCASIÃO DE USO
A34: Campo | B34: Resposta | C34: Orientação de preenchimento
A35: Público-alvo primário | C35: Demografia + comportamento. Demografia sozinha não é público-alvo.
A36: Público-alvo secundário | C36: Quem também compra, mas não é para quem a comunicação fala.
A37: Ocasião e frequência de uso | C37: Quando, onde, quantas vezes. Define tamanho de embalagem e giro.
A38: Dor / tensão do consumidor | C38: A frustração real com as soluções atuais, na linguagem do consumidor.
A39: Insight | C39: A verdade não óbvia que conecta a dor ao produto. Se soa como slogan, ainda não é insight.
A40: Barreira de adoção esperada | C40: Preço, ceticismo quanto ao benefício, hábito consolidado, percepção de marca. E como derrubar.
A42: 1.5 CONCEITO DE PRODUTO
A43: Campo | B43: Resposta | C43: Orientação de preenchimento
A44: Conceito em uma frase | C44: O que é, para quem, e o que entrega de diferente. Uma frase, sem adjetivo vazio.
A45: Benefício principal | C45: Um só. O que o consumidor lembraria 3 dias depois.
...

Sheet 2. Mercado
A1: 2 · MERCADO, DIMENSIONAMENTO E BENCHMARK
A2: Modelo bottom-up. Troque toda premissa estimada por dado de pesquisa assim que houver, e registre a fonte.
A4: 2.1 DIMENSIONAMENTO DA OPORTUNIDADE (TAM · SAM · SOM)
A5: Premissa | B5: Valor | C5: Unidade | D5: Fonte / justificativa
A6: População do público-alvo | C6: pessoas | D6: IBGE / painel de consumo. Recorte de idade, gênero, classe e região.
A7: Penetração da categoria | C7: % da pop. | D7: Percentual do público que compra a categoria em um ano.
A8: Consumidores da categoria | B8: =IFERROR(B6*B7,0) -> 0 | C8: pessoas | D8: Calculado: população × penetração.
A9: Frequência de compra | C9: un./ano | D9: Quantas unidades o mesmo consumidor compra por ano.
A10: Volume potencial da categoria | B10: =IFERROR(B8*B9,0) -> 0 | C10: un./ano | D10: Calculado: consumidores × frequência.
A11: Preço médio de gôndola da categoria | C11: R$/un. | D11: Puxe da média do benchmark em 2.2 ou de coleta própria de PDV.
A12: TAM — mercado potencial total | B12: =IFERROR(B10*B11,0) -> 0 | C12: R$/ano | D12: Calculado: volume potencial × preço médio.
A13: Cobertura de distribuição alcançável | C13: % do TAM | D13: Fatia do mercado que a nossa distribuição de fato consegue tocar.
A14: SAM — mercado endereçável | B14: =IFERROR(B12*B13,0) -> 0 | C14: R$/ano | D14: Calculado: TAM × cobertura.
A15: Share-alvo dentro do SAM (Ano 1) | C15: % | D15: Seja conservador. Share de lançamento raramente passa de 1 dígito no Ano 1.
A16: SOM — receita capturável no Ano 1 | B16: =IFERROR(B14*B15,0) -> 0 | C16: R$/ano | D16: Calculado: SAM × share-alvo. Este é o teto realista da meta.
A17: SOM em unidades | B17: =IFERROR(B16/B11,0) -> 0 | C17: un./ano | D17: Calculado: SOM ÷ preço médio. Compare com a meta de volume do briefing.
A19: Meta de volume declarada no briefing | B19: ='1. Briefing'!B28 -> 0 | C19: un./ano | D19: Puxado da aba 1 (célula 1.3).
A20: Consistência meta × SOM | B20: =IF(B17=0,"",IFERROR(B19/B17-1,"")) | C20: desvio | D20: Acima de 0% a meta é maior que o mercado capturável estimado. Ou a meta cai, ou a premissa sobe — com justificativa.
A22: 2.2 BENCHMARK COMPETITIVO — O QUE O CONSUMIDOR COMPRA HOJE
A23: Marca | B23: SKU / descrição | C23: Tamanho (ml ou g) | D23: Preço gôndola (R$) | E23: Preço por 100 ml/g (R$) | F23: Canal onde foi coletado | G23: Posicionamento | H23: Diferencial declarado no rótulo | I23: Data e fonte da coleta
A24: [EXEMPLO — apagar] | B24: Creme hidratante corporal 200 g | C24: 200 | D24: 18.9 | E24: =IF(OR(C24="",D24=""),"",IFERROR(D24/C24*100,"")) -> 9.45 | F24: Atacarejo | G24: Mainstream | H24: Hidratação 24h | I24: 01/03/2026 — coleta PDV
E25: =IF(OR(C25="",D25=""),"",IFERROR(D25/C25*100,""))
E26: =IF(OR(C26="",D26=""),"",IFERROR(D26/C26*100,""))
E27: =IF(OR(C27="",D27=""),"",IFERROR(D27/C27*100,""))
E28: =IF(OR(C28="",D28=""),"",IFERROR(D28/C28*100,""))
E29: =IF(OR(C29="",D29=""),"",IFERROR(D29/C29*100,""))
E30: =IF(OR(C30="",D30=""),"",IFERROR(D30/C30*100,""))
E31: =IF(OR(C31="",D31=""),"",IFERROR(D31/C31*100,""))
E32: =IF(OR(C32="",D32=""),"",IFERROR(D32/C32*100,""))
E33: =IF(OR(C33="",D33=""),"",IFERROR(D33/C33*100,""))
E34: =IF(OR(C34="",D34=""),"",IFERROR(D34/C34*100,""))
E35: =IF(OR(C35="",D35=""),"",IFERROR(D35/C35*100,""))
A36: Média do mercado | C36: =IFERROR(AVERAGE(C24:C35),0) -> 200 | D36: =IFERROR(AVERAGE(D24:D35),0) -> 18.9 | E36: =IFERROR(AVERAGE(E24:E35),0) -> 9.45 | F36: Média simples dos SKUs listados acima.
A37: Menor preço por 100 ml/g | E37: =IFERROR(MIN(E24:E35),0) -> 9.45 | F37: Piso da categoria — referência de entrada.
A38: Maior preço por 100 ml/g | E38: =IFERROR(MAX(E24:E35),0) -> 9.45 | F38: Teto da categoria — referência de premium.
A39: SKUs mapeados | B39: =COUNT(D24:D35) -> 1 | F39: Abaixo de 5 SKUs, o benchmark não sustenta decisão de preço.
A41: 2.3 LEITURA COMPETITIVA
A42: Pergunta | B42: Resposta
A43: Que espaço a categoria deixa vago (benefício, preço, tamanho, público)?
A44: Por que o líder é líder — preço, distribuição, marca ou produto?
...

Sheet 3. Formulação
A1: 3 · FORMULAÇÃO, TESTES E REGULATÓRIO
A2: Especificação técnica alvo, plano de testes e trilha regulatória. Toda referência normativa deve ser confirmada com Assuntos Regulatórios.
A4: 3.1 ESPECIFICAÇÃO TÉCNICA ALVO
A5: Parâmetro | B5: Alvo | C5: Faixa aceitável | D5: Método / observação
A6: Forma cosmética | D6: Creme, loção, gel, emulsão O/A ou A/O, sabonete, aerossol, roll-on, stick.
A7: pH | D7: Coerente com o local de aplicação e com o sistema conservante.
A8: Viscosidade | D8: Informar aparelho, spindle e rotação usados na leitura.
A9: Densidade | D9: Impacta enchimento nominal e custo por unidade.
A10: Cor e aspecto | D10: Descrição visual e padrão de referência.
A11: Fragrância | D11: Fornecedor, código, dosagem e alergênicos a declarar.
A12: Sistema conservante | D12: Definir com o microbiologista; precisa passar no desafio microbiológico.
A13: Teor de ativo claim-driver | D13: O percentual que sustenta o claim. Sem isso, o claim não se defende.
A14: Vida útil pretendida | D14: Prazo de validade alvo; precisa de lastro em estabilidade.
A15: Condições de armazenagem | D15: Temperatura e umidade recomendadas.
A16: Restrições de fórmula | D16: Vegano, sem parabenos, sem álcool, hipoalergênico, sem teste animal, biodegradável.
A18: 3.2 TRILHA REGULATÓRIA (BRASIL)
A19: Item | B19: Situação | C19: Responsável | D19: Prazo | E19: Referência de apoio (confirmar vigência) | F19: Custo estimado (R$) | G19: Concluído?
A20: Enquadramento do grau de risco (1 ou 2) | E20: RDC ANVISA nº 752/2022
A21: Definição do caminho: notificação ou registro | E21: RDC ANVISA nº 752/2022
A22: Empresa com AFE/licença compatível | E22: Lei 6.360/1976
A23: Fórmula qualitativa e quantitativa aprovada | E23: Dossiê técnico interno
A24: Verificação de substâncias restritas/proibidas | E24: Listas ANVISA vigentes
A25: Rotulagem obrigatória revisada | E25: Norma de rotulagem vigente
A26: Comprovação de cada claim pretendido | E26: Guia de claims / CONAR
A27: Estudo de estabilidade (acelerada e normal) | E27: Guia de estabilidade — ANVISA
A28: Compatibilidade fórmula × embalagem | E28: Protocolo interno
A29: Desafio microbiológico (challenge test) | E29: Protocolo interno / farmacopeia
A30: Avaliação de segurança | E30: Guia de segurança — ANVISA
A31: Teste dermatológico / de irritabilidade | E31: Laboratório clínico credenciado
... A34: Requisitos específicos do canal | E34: Exigência de cliente
A35: Custo regulatório total | E35: Soma da coluna. Este valor entra como investimento no Ano 0 (aba 6). | F35: =SUM(F20:F34) -> 0
A36: Avanço da trilha regulatória | B36: =IFERROR(COUNTIF(G20:G34,"Sim")/(COUNTA(G20:G34)-COUNTIF(G20:G34,"N/A")),0) -> 0 | E36: Itens "Sim" sobre o total aplicável.
A38: 3.3 TESTES BÁSICOS — CATÁLOGO PADRÃO APLICÁVEL A TODO O PORTFÓLIO
A39: Parâmetro | B39: Valor | F39: Comentário
A40: Nº de variações de fórmula a testar | B40: 1 | F40: Este número alimenta automaticamente a coluna de variações da tabela abaixo.
A42: Teste básico | B42: Nº de variações | C42: Valor unitário (R$/fórmula) | D42: Custo total (R$) | E42: Prazo (dias) | F42: O que decide | G42: Fonte do valor e do prazo
A43: Time kill | B43: =$B$40 -> 1 | C43: 1264 | D43: =IFERROR(B43*C43,0) -> 1264 | E43: 30 | F43: Valida o desempenho antimicrobiano da fórmula ao longo do tempo de contato. | G43: Valor e prazo informados pela equipe.
A44: Teste de segurança após time kill (dermatológico) | B44: =$B$40 -> 1 | C44: 600 | D44: =IFERROR(B44*C44,0) -> 600 | F44: Confirma a segurança cutânea da fórmula aprovada no time kill. Só começa depois dele. | G44: Valor informado pela equipe. PRAZO A CONFIRMAR com o laboratório.
A45: Eficácia (sniff test) + reemissões | B45: =$B$40 -> 1 | C45: 1900 | D45: =IFERROR(B45*C45,0) -> 1900 | F45: Avalia a performance percebida de fragrância, incluindo as reemissões previstas no pacote. | G45: Valor informado pela equipe. PRAZO A CONFIRMAR com o laboratório.
A46: Apreciabilidade cosmética (user experience) | B46: =$B$40 -> 1 | C46: 1350 | D46: =IFERROR(B46*C46,0) -> 1350 | F46: Mede a aceitação sensorial e a experiência de uso do produto. | G46: Valor informado pela equipe. PRAZO A CONFIRMAR com o laboratório.
...

Sheet 4. Embalagem
A1: 4 · EMBALAGEM, ROTULAGEM E LOGÍSTICA
A2: O custo unitário lançado aqui alimenta automaticamente o BOM da aba 5. O ferramental alimenta o investimento da aba 6.
A4: 4.1 ESTRUTURA DE EMBALAGEM, FORNECIMENTO E FERRAMENTAL
A5: Esta aba trata de especificação, fornecedor, lote mínimo, prazo e ferramental. O custo por componente é lançado na aba 5 (bloco 5.3), que é a fonte única de custo — aqui o total aparece apenas como consulta.
A6: Componente | B6: Material | C6: Especificação | D6: Fornecedor | E6: MOQ (un.) | F6: Lead time (dias) | G6: Nível na embalagem | H6: Ferramental / capex (R$) | I6: Un. por caixa
A7: Embalagem primária (frasco/pote/bisnaga) | C7: PEAD, PET, PP, vidro, alumínio
A8: Tampa / válvula / dosador | C8: Rosca, flip-top, pump, spray, roll-on
A9: Vedação / lacre | C9: Selo de indução, lacre de segurança
A10: Rótulo ou decoração | C10: Autoadesivo, sleeve, serigrafia, in-mould
A11: Cartucho / estojo | C11: Cartão duplex, quando houver
A12: Caixa de embarque | C12: Papelão ondulado; define paletização
A13: Filme / material de palete | C13: Stretch, cantoneira
A14: Outro componente | C14: Brinde, aplicador, encarte
A15: Custo de embalagem por unidade (calculado na aba 5) | G15: ='5. Custos'!J49 -> 0 | H15: =SUM(H7:H14) -> 0
A16: Maior lead time (caminho crítico de suprimentos) | F16: =IFERROR(MAX(F7:F14),0) -> 0
A17: Maior MOQ (lote mínimo que trava o projeto) | E17: =IFERROR(MAX(E7:E14),0) -> 0
A18: Capital imobilizado no primeiro lote de embalagem | G18: =IFERROR(MAX(E7:E14)*G15,0) -> 0 | H18: MOQ máximo × custo de embalagem por unidade. Em cenário de caixa curto, este número costuma pesar mais que o ferramental.
A20: 4.2 ROTULAGEM — CHECKLIST DE CONTEÚDO OBRIGATÓRIO E DE MARCA
A21: Item do rótulo | B21: Está previsto na arte? | C21: Responsável | D21: Observação
A22: Nome do produto e função
A23: Marca e identidade visual conforme manual (rosa institucional)
A24: Conteúdo nominal
A25: Composição completa em nomenclatura INCI
A26: Modo de uso
A27: Advertências e restrições de uso
A28: Lote e prazo de validade
A29: Identificação do fabricante ou importador e CNPJ
A30: Responsável técnico
A31: SAC, e-mail e site
A32: Número de notificação ou registro, quando exigido
A33: Código de barras GTIN
... A36: Claims aprovados pelo regulatório e pelo jurídico
A37: Completude da arte | B37: =IFERROR(COUNTIF(B22:B36,"Sim")/(COUNTA(B22:B36)-COUNTIF(B22:B36,"N/A")),0) -> 0 | D37: A arte não vai para fotolito abaixo de 100%.
A39: 4.3 DADOS LOGÍSTICOS
A40: Parâmetro | B40: Valor | C40: Unidade | D40: Observação
A41: Unidades por caixa de embarque | C41: un. | D41: Define o múltiplo de venda e a política de pedido mínimo.
A42: Caixas por camada | C42: cx
A43: Camadas por palete | C43: camadas
A44: Peso bruto da caixa | C44: kg | D44: Impacta frete e ergonomia.
A45: Cubagem da caixa | C45: m³ | D45: Produto leve e volumoso encarece frete por unidade.
...

Sheet 5. Custos
A1: 5 · FICHA DE CUSTO DO PRODUTO E FORMAÇÃO DE PREÇO
A2: Quatro grupos de custo (fórmula · embalagem · MOD · GGF) mais outros custos de produção, depois impostos de venda e margem bruta.
A4: 5.1 PARÂMETROS DA UNIDADE E DO LOTE
A5: Parâmetro | B5: Valor | C5: Unidade | D5: Comentário
A6: Gramatura declarada no rótulo | C6: g ou ml | D6: Conteúdo nominal. É o que o consumidor lê e o que a fiscalização cobra.
A7: Sobre-enchimento médio | B7: 0.01 | C7: % | D7: Quanto se enche a mais para nunca ficar abaixo do nominal. Encher 202 g para declarar 200 g é custo puro e quase sempre esquecido.
A8: Gramatura efetiva envasada | B8: =IFERROR(B6*(1+B7),0) -> 0 | C8: g ou ml | D8: Calculado: gramatura declarada × (1 + sobre-enchimento). É esta que consome matéria-prima.
A9: Perda de granel no processo e no envase | B9: 0.02 | C9: % | D9: Resíduo de tanque, tubulação, purga de linha e reprocesso descartado.
A10: Tamanho do lote de produção | C10: un. | D10: O custo unitário muda com o lote. Sem definir o lote, o custeio de MOD e GGF é ficção.
A11: Velocidade da linha | C11: un./h | D11: Produção efetiva por hora, já considerando as paradas normais.
A12: Horas de produção do lote | B12: =IFERROR(B10/B11,0) -> 0 | C12: h | D12: Calculado: lote ÷ velocidade.
A13: Horas de setup, limpeza e troca de lote | C13: h | D13: Higienização entre lotes é obrigatória em cosmético e costuma pesar mais que a própria produção em lote pequeno.
A14: Horas totais ocupadas pelo lote | B14: =B12+B13 -> 0 | C14: h | D14: Calculado: produção + setup. É esta hora que MOD e GGF cobram.
A16: 5.2 GRUPO 1 — MATÉRIAS-PRIMAS DA FORMULAÇÃO
A17: O custo da matéria-prima é o preço posto na fábrica MENOS os impostos que a empresa recupera na compra. Lançar o preço da nota cheio superestima o custo e faz o produto parecer menos rentável do que é. Confirme com a Contabilidade quais créditos o regime tributário da empresa aproveita.
A18: Matéria-prima | B18: Função / INCI | C18: % na fórmula | D18: Unidade | E18: Preço bruto (R$/kg) | F18: Frete inbound (R$/kg) | G18: Impostos recuperáveis (%) | H18: Custo líquido (R$/kg) | I18: Perda específica (%) | J18: Custo por unidade (R$) | K18: % do custo | L18: Fornecedor / observação
A19: [EXEMPLO — apagar] Água purificada | B19: Aqua — veículo | C19: 0.7 | D19: kg | E19: 0.02 | H19: =IF(E19="","",(E19+F19)*(1-G19)) -> 0.02 | J19: =IF(OR(C19="",E19=""),"",IFERROR(H19*C19*$B$8/1000/(1-$B$9)/(1-I19),"")) -> 0 | K19: =IF(J19="","",IFERROR(J19/$B$123,""))
D20: kg | H20: =IF(E20="","",(E20+F20)*(1-G20)) | J20: =IF(OR(C20="",E20=""),"",IFERROR(H20*C20*$B$8/1000/(1-$B$9)/(1-I20),"")) | K20: =IF(J20="","",IFERROR(J20/$B$123,""))
D21: kg | H21: =IF(E21="","",(E21+F21)*(1-G21)) | J21: =IF(OR(C21="",E21=""),"",IFERROR(H21*C21*$B$8/1000/(1-$B$9)/(1-I21),"")) | K21: =IF(J21="","",IFERROR(J21/$B$123,""))
D22: kg | H22: =IF(E22="","",(E22+F22)*(1-G22)) | J22: =IF(OR(C22="",E22=""),"",IFERROR(H22*C22*$B$8/1000/(1-$B$9)/(1-I22),"")) | K22: =IF(J22="","",IFERROR(J22/$B$123,""))
D23: kg | H23: =IF(E23="","",(E23+F23)*(1-G23)) | J23: =IF(OR(C23="",E23=""),"",IFERROR(H23*C23*$B$8/1000/(1-$B$9)/(1-I23),"")) | K23: =IF(J23="","",IFERROR(J23/$B$123,""))
D24: kg | H24: =IF(E24="","",(E24+F24)*(1-G24)) | J24: =IF(OR(C24="",E24=""),"",IFERROR(H24*C24*$B$8/1000/(1-$B$9)/(1-I24),"")) | K24: =IF(J24="","",IFERROR(J24/$B$123,""))
D25: kg | H25: =IF(E25="","",(E25+F25)*(1-G25)) | J25: =IF(OR(C25="",E25=""),"",IFERROR(H25*C25*$B$8/1000/(1-$B$9)/(1-I25),"")) | K25: =IF(J25="","",IFERROR(J25/$B$123,""))
D26: kg | H26: =IF(E26="","",(E26+F26)*(1-G26)) | J26: =IF(OR(C26="",E26=""),"",IFERROR(H26*C26*$B$8/1000/(1-$B$9)/(1-I26),"")) | K26: =IF(J26="","",IFERROR(J26/$B$123,""))
D27: kg | H27: =IF(E27="","",(E27+F27)*(1-G27)) | J27: =IF(OR(C27="",E27=""),"",IFERROR(H27*C27*$B$8/1000/(1-$B$9)/(1-I27),"")) | K27: =IF(J27="","",IFERROR(J27/$B$123,""))
D28: kg | H28: =IF(E28="","",(E28+F28)*(1-G28)) | J28: =IF(OR(C28="",E28=""),"",IFERROR(H28*C28*$B$8/1000/(1-$B$9)/(1-I28),"")) | K28: =IF(J28="","",IFERROR(J28/$B$123,""))
D29: kg | H29: =IF(E29="","",(E29+F29)*(1-G29)) | J29: =IF(OR(C29="",E29=""),"",IFERROR(H29*C29*$B$8/1000/(1-$B$9)/(1-I29),"")) | K29: =IF(J29="","",IFERROR(J29/$B$123,""))
D30: kg | H30: =IF(E30="","",(E30+F30)*(1-G30)) | J30: =IF(OR(C30="",E30=""),"",IFERROR(H30*C30*$B$8/1000/(1-$B$9)/(1-I30),"")) | K30: =IF(J30="","",IFERROR(J30/$B$123,""))
D31: kg | H31: =IF(E31="","",(E31+F31)*(1-G31)) | J31: =IF(OR(C31="",E31=""),"",IFERROR(H31*C31*$B$8/1000/(1-$B$9)/(1-I31),"")) | K31: =IF(J31="","",IFERROR(J31/$B$123,""))
D32: kg | H32: =IF(E32="","",(E32+F32)*(1-G32)) | J32: =IF(OR(C32="",E32=""),"",IFERROR(H32*C32*$B$8/1000/(1-$B$9)/(1-I32),"")) | K32: =IF(J32="","",IFERROR(J32/$B$123,""))
A33: Subtotal · matérias-primas da formulação | C33: =SUM(C19:C32) -> 0.7 | J33: =SUM(J19:J32) -> 0 | K33: =IFERROR(J33/$B$123,0) -> 0
A34: Validação do fechamento da fórmula | C34: =IF(ABS(C33-1)<0.0001,"OK — 100%","AJUSTAR") -> AJUSTAR
A35: Enquanto a soma dos percentuais não fechar 100%, o custo por quilo de granel está errado.
A37: 5.3 GRUPO 2 — EMBALAGEM
A38: Uma linha por componente, dos três níveis: primária (contato com o produto), secundária (cartucho, display) e terciária (caixa de embarque, filme, palete). Na coluna Origem, diga se o item é comprado pronto ou transformado internamente — se for transformado, calcule o custo por peça em 5.4 e traga o resultado para a coluna de preço.
A39: Componente | B39: Origem | C39: Qtd por unidade | D39: Unidade | E39: Preço bruto (R$/un.) | F39: Frete inbound (R$/un.) | G39: Impostos recuperáveis (%) | H39: Custo líquido (R$/un.) | I39: Refugo (%) | J39: Custo por unidade (R$) | K39: % do custo | L39: Fornecedor / nível
A40: Embalagem primária (frasco, pote, bisnaga, lata) | D40: un. | H40: =IF(E40="","",(E40+F40)*(1-G40)) | J40: =IF(OR(C40="",E40=""),"",IFERROR(H40*C40/(1-I40),"")) | K40: =IF(J40="","",IFERROR(J40/$B$123,"")) | L40: Primária
A41: Tampa, válvula, pump ou dosador | D41: un. | H41: =IF(E41="","",(E41+F41)*(1-G41)) | J41: =IF(OR(C41="",E41=""),"",IFERROR(H41*C41/(1-I41),"")) | K41: =IF(J41="","",IFERROR(J41/$B$123,"")) | L41: Primária
A42: Lacre, selo de indução ou vedante | D42: un. | H42: =IF(E42="","",(E42+F42)*(1-G42)) | J42: =IF(OR(C42="",E42=""),"",IFERROR(H42*C42/(1-I42),"")) | K42: =IF(J42="","",IFERROR(J42/$B$123,"")) | L42: Primária
A43: Rótulo, sleeve ou decoração | D43: un. | H43: =IF(E43="","",(E43+F43)*(1-G43)) | J43: =IF(OR(C43="",E43=""),"",IFERROR(H43*C43/(1-I43),"")) | K43: =IF(J43="","",IFERROR(J43/$B$123,"")) | L43: Primária
...

Sheet 6. Viabilidade
A1: 6 · VIABILIDADE ECONÔMICA — 3 ANOS
A2: Puxa preço e custo da aba 5 e investimentos das abas 3 e 4. Preencha apenas crescimento, percentuais de despesa e taxa de desconto.
A4: 6.1 PREMISSAS
A5: Premissa | B5: Valor | F5: Comentário
A6: Crescimento de volume — Ano 2 | B6: 0.25 | F6: Sobre o volume do Ano 1. Lançamento costuma crescer no Ano 2 pela distribuição, não pelo giro.
A7: Crescimento de volume — Ano 3 | B7: 0.15 | F7: Maturação. Crescimento de dois dígitos altos no Ano 3 precisa de justificativa.
A8: Marketing e trade (% da receita líquida) | B8: 0.08 | F8: Inclui mídia, trade, encarte e ativação de PDV.
A9: Despesas comerciais e estrutura (% da RL) | B9: 0.06 | F9: Comissão, representação, estrutura de vendas alocada.
A10: Taxa de desconto anual | B10: 0.18 | F10: Custo de capital. Em cenário de caixa curto e dívida cara, o piso é o custo da dívida — alinhar com a Diretoria Financeira.
A11: Outros investimentos no Ano 0 | F11: Consultoria, arte, fotografia, ativação de lançamento, cadastro em clientes.
A12: Valores de crescimento e de despesa são ilustrativos — substitua pelos seus.
A14: 6.2 DEMONSTRATIVO INCREMENTAL DO PROJETO
A15: Linha | B15: Ano 0 | C15: Ano 1 | D15: Ano 2 | E15: Ano 3 | F15: Comentário
A16: Volume (un.) | C16: =IFERROR('1. Briefing'!B28,0) -> 0 | D16: =C16*(1+$B$6) -> 0 | E16: =D16*(1+$B$7) -> 0 | F16: Ano 1 vem da meta do briefing; Anos 2 e 3 aplicam o crescimento premissado.
A17: Preço de fábrica (R$/un.) | C17: ='5. Custos'!B129 -> 0 | D17: =C17 -> 0 | E17: =D17 -> 0 | F17: Puxado da aba 5. Mantido nominal — sem reajuste. Se houver política de preço, ajuste aqui.
A18: Receita bruta | C18: =C16*C17 -> 0 | D18: =D16*D17 -> 0 | E18: =E16*E17 -> 0 | F18: Volume × preço de fábrica.
A19: Receita líquida | C19: =C16*'5. Custos'!$B$148 -> 0 | D19: =D16*'5. Custos'!$B$148 -> 0 | E19: =E16*'5. Custos'!$B$148 -> 0 | F19: Volume × receita líquida unitária da aba 5 (já descontados impostos e verbas).
A20: (−) Custo industrial | C20: =-C16*'5. Custos'!$B$123 -> 0 | D20: =-D16*'5. Custos'!$B$123 -> 0 | E20: =-E16*'5. Custos'!$B$123 -> 0 | F20: Volume × CPV unitário da aba 5.
A21: ► Margem bruta | C21: =C19+C20 -> 0 | D21: =D19+D20 -> 0 | E21: =E19+E20 -> 0 | F21: Receita líquida − custo industrial. As despesas variáveis de venda estão detalhadas na aba 5.
A22: (−) Marketing e trade | C22: =-C19*$B$8 -> 0 | D22: =-D19*$B$8 -> 0 | E22: =-E19*$B$8 -> 0 | F22: Percentual da receita líquida definido em 6.1.
A23: (−) Despesas comerciais e estrutura | C23: =-C19*$B$9 -> 0 | D23: =-D19*$B$9 -> 0 | E23: =-E19*$B$9 -> 0 | F23: Percentual da receita líquida definido em 6.1.
A24: ► Resultado contributivo do projeto | C24: =C21+C22+C23 -> 0 | D24: =D21+D22+D23 -> 0 | E24: =E21+E22+E23 -> 0 | F24: O que o projeto devolve ao caixa antes de investimento e de rateio de fixos corporativos.
A26: 6.3 INVESTIMENTO (ANO 0) E FLUXO DE CAIXA
A27: Linha | B27: Ano 0 | C27: Ano 1 | D27: Ano 2 | E27: Ano 3 | F27: Comentário
A28: Ferramental e moldes | B28: ='4. Embalagem'!H15 -> 0 | F28: Puxado da aba 4.
A29: Regulatório | B29: ='3. Formulação'!F35 -> 0 | F29: Puxado da aba 3.
A30: Pesquisa, desenvolvimento e testes | B30: ='3. Formulação'!B76 -> 5114 | F30: Puxado da aba 3.
A31: Capital de giro — primeiro lote de embalagem | B31: ='4. Embalagem'!G18 -> 0 | F31: Puxado da aba 4. MOQ máximo × custo de embalagem por unidade.
A32: Outros investimentos | B32: =$B$11 -> 0 | F32: Definido em 6.1.
A33: ► Investimento total | B33: =SUM(B28:B32) -> 5114 | F33: Soma das linhas acima. Compare com o capex máximo autorizado no briefing.
A34: Fluxo de caixa livre | B34: =-B33 -> -5114 | C34: =C24 -> 0 | D34: =D24 -> 0 | E34: =E24 -> 0 | F34: Ano 0 negativo (desembolso); anos seguintes, o resultado contributivo.
A35: Fluxo de caixa acumulado | B35: =B34 -> -5114 | C35: =B35+C34 -> -5114 | D35: =C35+D34 -> -5114 | E35: =D35+E34 -> -5114 | F35: Quando vira positivo, o projeto se pagou.
A37: 6.4 INDICADORES DE DECISÃO
A38: Indicador | B38: Resultado | F38: Leitura
A39: VPL (Valor Presente Líquido) | B39: =IFERROR(NPV($B$10,C34:E34)+B34,0) -> -5114 | F39: Positivo, o projeto cria valor acima do custo de capital. Negativo, destrói.
A40: TIR (Taxa Interna de Retorno) | B40: =IFERROR(IRR(B34:E34),"n/d") -> n/d | F40: Compare com a taxa de desconto de 6.1. Abaixo dela, o dinheiro rende mais em outro lugar.
A41: Payback (anos) | B41: =IF(B35>=0,0,IF(C35>=0,IFERROR(-B34/C34,""),IF(D35>=0,IFERROR(1-C35/D34,""),IF(E35>=0,IFERROR(2-D35/E34,""),"Acima de 3 anos")))) -> Acima de 3 anos | F41: Em caixa curto, payback acima de 24 meses é decisão de Diretoria, não de área.
A42: ROI em 3 anos | B42: =IF(B33=0,0,(SUM(C34:E34)-B33)/B33) -> -1 | F42: Retorno acumulado sobre o investimento do Ano 0.
A43: Investimento × capex autorizado | B43: =IF('1. Briefing'!B67="","Capex não informado no briefing",IF(B33<='1. Briefing'!B67,"Dentro do teto autorizado","ESTOURA o teto autorizado")) -> Capex não informado no briefing | F43: Confronta o investimento total com o teto declarado na aba 1.
A44: Margem bruta consolidada — Ano 1 | B44: =IF(C19=0,0,C21/C19) -> 0 | F44: Deve bater com a margem bruta unitária da aba 5. Divergência indica premissa inconsistente.

Sheet 7. Scorecard
A1: 7 · SCORECARD DE PRIORIZAÇÃO DE PORTFÓLIO
A2: Pesos somam 100%. Notas de 1 a 5. O score ponderado define a ordem da fila de desenvolvimento.
A4: 7.1 CRITÉRIOS
A5: Critério | B5: Peso | C5: Nota (1-5) | D5: Ponderado | E5: Como pontuar
A6: Aderência à estratégia e à marca | B6: 0.15 | D6: =IF(C6="","",B6*C6) | E6: 5 = usa o território da Leite de Rosas sem forçar. 1 = marca não tem autoridade nenhuma nessa promessa.
A7: Tamanho da oportunidade (SOM) | B7: 0.15 | D7: =IF(C7="","",B7*C7) | E7: Ancorar no SOM da aba 2. 5 = move o ponteiro do faturamento. 1 = nicho que não paga o esforço.
A8: Margem de contribuição | B8: 0.15 | D8: =IF(C8="","",B8*C8) | E8: Ancorar no percentual da aba 5. 5 = bem acima da margem média da casa. 1 = abaixo do alvo.
A9: Investimento requerido (quanto menor, melhor) | B9: 0.1 | D9: =IF(C9="","",B9*C9) | E9: 5 = quase sem capex, roda em ativo existente ou terceirizado. 1 = exige linha nova.
A10: Velocidade até o mercado | B10: 0.1 | D10: =IF(C10="","",B10*C10) | E10: 5 = na gôndola em até 6 meses. 1 = mais de 18 meses.
A11: Complexidade técnica e regulatória (quanto menor, melhor) | B11: 0.08 | D11: =IF(C11="","",B11*C11) | E11: 5 = fórmula conhecida, grau de risco 1. 1 = tecnologia nova e registro exigido.
A12: Sinergia fabril e logística | B12: 0.07 | D12: =IF(C12="","",B12*C12) | E12: 5 = mesma linha, mesmo fornecedor, mesma caixa. 1 = tudo novo.
A13: Força do conceito para o consumidor | B13: 0.1 | D13: =IF(C13="","",B13*C13) | E13: Ancorar em teste de conceito. 5 = intenção de compra alta e benefício claro. 1 = ninguém entendeu.
A14: Baixo risco de canibalização (quanto menor, melhor) | B14: 0.05 | D14: =IF(C14="","",B14*C14) | E14: 5 = volume vem de fora da casa. 1 = tira volume direto do carro-chefe.
A15: Sustentabilidade da vantagem | B15: 0.05 | D15: =IF(C15="","",B15*C15) | E15: 5 = difícil de copiar em 12 meses. 1 = concorrente replica em um trimestre.
A16: Soma dos pesos | B16: =SUM(B6:B15) -> 1 | E16: =IF(ABS(B16-1)<0.0001,"OK — pesos somam 100%","AJUSTAR — os pesos precisam somar 100%") -> OK — pesos somam 100%
A17: SCORE PONDERADO (1 a 5) | C17: =COUNT(C6:C15) -> 0 | D17: =IFERROR(SUMPRODUCT(B6:B15,C6:C15),0) -> 0 | E17: Soma dos ponderados. A coluna C mostra quantos critérios já foram pontuados — abaixo de 10, o score está incompleto.
A18: CLASSIFICAÇÃO | B18: =IF(COUNT(C6:C15)<10,"Incompleto — pontue todos os critérios",IF(D17>=4,"PRIORIDADE MÁXIMA — entra na fila agora",IF(D17>=3.2,"APROVADO — entra na fila conforme capacidade",IF(D17>=2.5,"REVISAR — reformular conceito, custo ou escopo","DESCARTAR — não justifica o esforço")))) -> Incompleto — pontue todos os critérios | E18: Faixas de corte definidas pela gestão de portfólio. Ajuste-as se a régua da casa for outra.
A20: 7.2 COMPARATIVO COM OUTROS PROJETOS DA FILA
A21: Projeto | B21: Score | C21: Investimento (R$) | D21: Payback (anos) | E21: Situação
A22: Este projeto | B22: =D17 -> 0 | C22: ='6. Viabilidade'!B33 -> 5114 | D22: ='6. Viabilidade'!B41 -> Acima de 3 anos | E22: =B18 -> Incompleto — pontue todos os critérios
A29: Posição deste projeto na fila | B29: =IFERROR(RANK(B22,B22:B28,0),0) -> 1 | E29: Ranking por score entre os projetos listados. Preencha os concorrentes internos para a comparação fazer sentido.

Sheet 8. Cronograma
A1: 8 · CRONOGRAMA STAGE-GATE
A2: Preencha a data de início e as durações. As datas de término e o encadeamento são calculados.
A4: 8.1 ÂNCORA DO CRONOGRAMA
B5: Parâmetro | C5: Valor | G5: Comentário
B6: Data de início do projeto | G6: Sem esta data, nenhuma outra é calculada.
A8: 8.2 FASES E GATES
A9: # | B9: Fase / entrega | C9: Gate de saída | D9: Início | E9: Duração (dias) | F9: Término | G9: Responsável | H9: % concluído | I9: Status
A10: 1 | B10: Exploração e abertura do briefing | C10: G0 — ideia aprovada | D10: =IF($C$6="","",$C$6) | E10: 10 | F10: =IF(OR(D10="",E10=""),"",D10+E10) | H10: 0
A11: 2 | B11: Pesquisa de mercado e benchmark de PDV | C11: G1 — conceito validado | D11: =IF(F10="","",F10+1) | E11: 20 | F11: =IF(OR(D11="",E11=""),"",D11+E11) | H11: 0
A12: 3 | B12: Definição de conceito e teste com consumidor | C12: G1 — conceito validado | D12: =IF(F11="","",F11+1) | E12: 25 | F12: =IF(OR(D12="",E12=""),"",D12+E12) | H12: 0
A13: 4 | B13: Desenvolvimento de fórmula em bancada | C13: G2 — viabilidade técnica | D13: =IF(F12="","",F12+1) | E13: 45 | F13: =IF(OR(D13="",E13=""),"",D13+E13) | H13: 0
A14: 5 | B14: Definição de embalagem e cotação de fornecedores | C14: G2 — viabilidade técnica | D14: =IF(F13="","",F13+1) | E14: 30 | F14: =IF(OR(D14="",E14=""),"",D14+E14) | H14: 0
A15: 6 | B15: Custeio, precificação e caso de negócio | C15: G2 — viabilidade econômica | D15: =IF(F14="","",F14+1) | E15: 15 | F15: =IF(OR(D15="",E15=""),"",D15+E15) | H15: 0
A16: 7 | B16: Aprovação do gate de investimento | C16: G3 — GO de desenvolvimento | D16: =IF(F15="","",F15+1) | E16: 10 | F16: =IF(OR(D16="",E16=""),"",D16+E16) | H16: 0
A17: 8 | B17: Estabilidade, compatibilidade e microbiologia | C17: G3 — dossiê técnico | D17: =IF(F16="","",F16+1) | E17: 90 | F17: =IF(OR(D17="",E17=""),"",D17+E17) | H17: 0
A18: 9 | B18: Regulatório: notificação ou registro | C18: G3 — regularização | D18: =IF(F17="","",F17+1) | E18: 45 | F18: =IF(OR(D18="",E18=""),"",D18+E18) | H18: 0
A19: 10 | B19: Design de embalagem, arte e fotolito | C19: G4 — arte liberada | D19: =IF(F18="","",F18+1) | E19: 40 | F19: =IF(OR(D19="",E19=""),"",D19+E19) | H19: 0
A20: 11 | B20: Ferramental, amostras e aprovação de fornecedores | C20: G4 — suprimentos prontos | D20: =IF(F19="","",F19+1) | E20: 60 | F20: =IF(OR(D20="",E20=""),"",D20+E20) | H20: 0
A21: 12 | B21: Piloto industrial e validação de linha | C21: G4 — processo validado | D21: =IF(F20="","",F20+1) | E21: 20 | F21: =IF(OR(D21="",E21=""),"",D21+E21) | H21: 0
A22: 13 | B22: Cadastro comercial, GTIN e ficha técnica | C22: G5 — pronto para vender | D22: =IF(F21="","",F21+1) | E22: 15 | F22: =IF(OR(D22="",E22=""),"",D22+E22) | H22: 0
... A25: 16 | B25: Acompanhamento pós-lançamento (90 dias) | C25: Revisão de KPIs | D25: =IF(F24="","",F24+1) | E25: 90 | F25: =IF(OR(D25="",E25=""),"",D25+E25) | H25: 0
B26: Duração total (sequencial) | E26: =SUM(E10:E25) -> 565 | F26: =IF(F25="","",F25) | G26: Cenário 100% sequencial. | H26: =IFERROR(AVERAGE(H10:H25),0) -> 0
B27: Duração em meses | E27: =IFERROR(SUM(E10:E25)/30,0) -> 18.833333
B28: Data prevista de gôndola | F28: =IF(F24="","",F24) | G28: Término da fase de sell-in e lançamento.
B29: Dias restantes até a gôndola | F29: =IF(F28="","",F28-TODAY()) | G29: Recalcula sozinho a cada abertura do arquivo.
A31: 8.3 PARALELIZAÇÃO — ONDE DÁ PARA GANHAR TEMPO
A32: O cálculo acima é sequencial e propositalmente pessimista: serve de teto. Na prática, estabilidade, regulatório, arte e ferramental correm em paralelo, e é aí que se ganham meses. Estabilidade é quase sempre o caminho crítico — comece por ela assim que a fórmula estiver congelada, não depois da arte aprovada. Em cenário de caixa curto, atrasar o ferramental até a fórmula estar validada evita imobilizar dinheiro em molde de um produto que ainda pode mudar. Registre aqui, fase a fase, o que roda em paralelo e qual é a dependência real entre elas.

Sheet 9. Riscos
A1: 9 · MATRIZ DE RISCOS DO PROJETO
A2: Probabilidade e impacto de 1 a 5. Severidade e nível são calculados. Risco sem dono e sem prazo não é risco tratado.
A4: 9.1 RISCOS MAPEADOS
A5: # | B5: Risco | C5: Categoria | D5: Prob. (1-5) | E5: Impacto (1-5) | F5: Severidade | G5: Nível | H5: Mitigação | I5: Responsável | J5: Prazo
A6: 1 | B6: Custo de matéria-prima acima do orçado derruba a margem | C6: Custo | F6: =IF(OR(D6="",E6=""),"",D6*E6) | G6: =IF(F6="","",IF(F6>=15,"CRÍTICO",IF(F6>=9,"ALTO",IF(F6>=4,"MÉDIO","BAIXO"))))
A7: 2 | B7: Varejo não aceita o preço e exige verba adicional | C7: Comercial | F7: =IF(OR(D7="",E7=""),"",D7*E7) | G7: =IF(F7="","",IF(F7>=15,"CRÍTICO",IF(F7>=9,"ALTO",IF(F7>=4,"MÉDIO","BAIXO"))))
A8: 3 | B8: MOQ de embalagem imobiliza caixa acima do previsto | C8: Financeiro | F8: =IF(OR(D8="",E8=""),"",D8*E8) | G8: =IF(F8="","",IF(F8>=15,"CRÍTICO",IF(F8>=9,"ALTO",IF(F8>=4,"MÉDIO","BAIXO"))))
A9: 4 | B9: Estabilidade reprova e obriga a refazer a fórmula | C9: Técnico | F9: =IF(OR(D9="",E9=""),"",D9*E9) | G9: =IF(F9="","",IF(F9>=15,"CRÍTICO",IF(F9>=9,"ALTO",IF(F9>=4,"MÉDIO","BAIXO"))))
A10: 5 | B10: Notificação ou registro atrasa e trava o lançamento | C10: Regulatório | F10: =IF(OR(D10="",E10=""),"",D10*E10) | G10: =IF(F10="","",IF(F10>=15,"CRÍTICO",IF(F10>=9,"ALTO",IF(F10>=4,"MÉDIO","BAIXO"))))
A11: 6 | B11: Claim sem lastro gera questionamento de órgão ou concorrente | C11: Jurídico | F11: =IF(OR(D11="",E11=""),"",D11*E11) | G11: =IF(F11="","",IF(F11>=15,"CRÍTICO",IF(F11>=9,"ALTO",IF(F11>=4,"MÉDIO","BAIXO"))))
A12: 7 | B12: Produto canibaliza o carro-chefe em vez de somar volume | C12: Portfólio | F12: =IF(OR(D12="",E12=""),"",D12*E12) | G12: =IF(F12="","",IF(F12>=15,"CRÍTICO",IF(F12>=9,"ALTO",IF(F12>=4,"MÉDIO","BAIXO"))))
A13: 8 | B13: Concorrente lança conceito equivalente antes | C13: Competitivo | F13: =IF(OR(D13="",E13=""),"",D13*E13) | G13: =IF(F13="","",IF(F13>=15,"CRÍTICO",IF(F13>=9,"ALTO",IF(F13>=4,"MÉDIO","BAIXO"))))
A14: 9 | B14: Fornecedor único de componente crítico atrasa ou falha | C14: Suprimentos | F14: =IF(OR(D14="",E14=""),"",D14*E14) | G14: =IF(F14="","",IF(F14>=15,"CRÍTICO",IF(F14>=9,"ALTO",IF(F14>=4,"MÉDIO","BAIXO"))))
A15: 10 | B15: Giro abaixo do previsto gera devolução e ruptura de confiança no canal | C15: Comercial | F15: =IF(OR(D15="",E15=""),"",D15*E15) | G15: =IF(F15="","",IF(F15>=15,"CRÍTICO",IF(F15>=9,"ALTO",IF(F15>=4,"MÉDIO","BAIXO"))))
A16: 11 | B16: Capacidade fabril insuficiente no pico de demanda | C16: Operacional | F16: =IF(OR(D16="",E16=""),"",D16*E16) | G16: =IF(F16="","",IF(F16>=15,"CRÍTICO",IF(F16>=9,"ALTO",IF(F16>=4,"MÉDIO","BAIXO"))))
A17: 12 | B17: Investimento estoura o capex autorizado | C17: Financeiro | F17: =IF(OR(D17="",E17=""),"",D17*E17) | G17: =IF(F17="","",IF(F17>=15,"CRÍTICO",IF(F17>=9,"ALTO",IF(F17>=4,"MÉDIO","BAIXO"))))
B18: Severidade média da carteira de riscos | F18: =IFERROR(AVERAGE(F6:F17),0) -> 0
B19: Riscos críticos ou altos | F19: =COUNTIF(G6:G17,"CRÍTICO")+COUNTIF(G6:G17,"ALTO") -> 0 | G19: Todo risco crítico ou alto precisa de mitigação escrita, dono e prazo antes do gate de investimento.
B20: Riscos altos sem mitigação definida | F20: =COUNTIFS(G6:G17,"CRÍTICO",H6:H17,"")+COUNTIFS(G6:G17,"ALTO",H6:H17,"") -> 0 | G20: Precisa chegar a zero antes da aprovação.
A22: 9.2 CRITÉRIO DE SEVERIDADE
A23: Faixa | B23: Nível | C23: Ação exigida
A24: 15 a 25 | B24: CRÍTICO | C24: Plano de mitigação aprovado pela Diretoria antes do gate. Sem plano, sem GO.
A25: 9 a 14 | B25: ALTO | C25: Mitigação com dono e prazo, revisada a cada gate.
A26: 4 a 8 | B26: MÉDIO | C26: Monitorar e reavaliar a cada gate.
A27: 1 a 3 | B27: BAIXO | C27: Registrar e seguir.

Sheet 10. Aprovação
A1: 10 · CHECKLIST DE GATE E REGISTRO DE APROVAÇÃO
A2: Documento de decisão. Vai assinado para o comitê junto com as abas 6, 7 e 9.
A4: 10.1 CHECKLIST DE PRONTIDÃO PARA O GATE
A5: # | B5: Item | C5: Gate | D5: Status | E5: Responsável | F5: Data | G5: Observação
A6: 1 | B6: Briefing preenchido por completo (aba 1) | C6: G1
A7: 2 | B7: Dimensionamento de mercado com fonte declarada (aba 2) | C7: G1
A8: 3 | B8: Benchmark com no mínimo 5 SKUs coletados em PDV (aba 2) | C8: G1
A9: 4 | B9: Conceito testado com consumidor | C9: G1
A10: 5 | B10: Especificação técnica alvo definida (aba 3) | C10: G2
A11: 6 | B11: Enquadramento regulatório confirmado (aba 3) | C11: G2
A12: 7 | B12: Cada claim com plano de comprovação (aba 3) | C12: G2
A13: 8 | B13: Embalagem cotada com no mínimo 2 fornecedores (aba 4) | C13: G2
A14: 9 | B14: BOM fechando 100% e custo industrial calculado (aba 5) | C14: G2
A15: 10 | B15: Margem de contribuição igual ou acima do alvo (aba 5) | C15: G2
A16: 11 | B16: Caso de negócio com VPL, TIR e payback (aba 6) | C16: G3
A17: 12 | B17: Investimento dentro do capex autorizado (aba 6) | C17: G3
... A27: 22 | B27: Primeiro lote produzido e disponível | C27: G5
B28: Prontidão geral | D28: =IFERROR(COUNTIF(D6:D27,"Sim")/(COUNTA(D6:D27)-COUNTIF(D6:D27,"N/A")),0) -> 0 | G28: Itens "Sim" sobre o total aplicável.
B29: Pendências abertas | D29: =COUNTIF(D6:D27,"Não") -> 0 | G29: Itens marcados como Não.
A31: 10.2 SÍNTESE PARA O COMITÊ
B32: Indicador | C32: Valor | G32: Origem
B33: Score de priorização | C33: ='7. Scorecard'!D17 -> 0 | G33: Aba 7
B34: Classificação | C34: ='7. Scorecard'!B18 -> Incompleto — pontue todos os critérios | G34: Aba 7
B35: Margem de contribuição | C35: ='5. Custos'!B160 -> 0 | G35: Aba 5
B36: Veredito de precificação | C36: ='5. Custos'!B177 -> Preencha as premissas | G36: Aba 5
B37: Investimento total | C37: ='6. Viabilidade'!B33 -> 5114 | G37: Aba 6
B38: VPL | C38: ='6. Viabilidade'!B39 -> -5114 | G38: Aba 6
B39: TIR | C39: ='6. Viabilidade'!B40 -> n/d | G39: Aba 6
B40: Payback (anos) | C40: ='6. Viabilidade'!B41 -> Acima de 3 anos | G40: Aba 6
B41: Riscos críticos ou altos | C41: ='9. Riscos'!F19 -> 0 | G41: Aba 9
B42: Prontidão do checklist | C42: =D28 -> 0 | G42: Aba 10
A44: 10.3 DECISÃO
B45: Campo | C45: Registro | G45: Observação
B46: Decisão do comitê | G46: GO | GO condicionado | AJUSTAR e retornar | NO-GO
B47: Condicionantes da aprovação | G47: O que precisa acontecer para o GO se manter válido.
B48: Data da decisão | G48: Data da reunião de gate.
B49: Próximo gate e data prevista | G49: Quando o projeto volta ao comitê.
B50: Aprovador — Marketing / Produto | G50: Nome e data.
B51: Aprovador — Industrial / P&D | G51: Nome e data.
B52: Aprovador — Comercial | G52: Nome e data.
...
